Workbook

Sheet County Plans
A1: GridAid county plans: 5 urban and 5 rural counties
A2: Blue = inputs and data. Black = formulas. Green = linked from another cell block. Yellow = placeholder the county should set. Change any blue cell and every budget updates.
A4: 1. Generator types (one site = one 100 kW setup)
A5: Type | B5: Cost per site ($) | C5: Fuel | D5: Fuel use per hour, full load | E5: Fuel unit | F5: Fuel price ($ per unit) | G5: Fuel cost per day, per site ($) | H5: Rental per week, per site ($) | I5: What it is, source and notes
A6: Hookup only (rent a generator in an outage) | B6: 10000 | C6: Diesel (rented unit) | D6: 7.4 | E6: gallons | F6: 6.179 | G6: =D6*24*F6 -> 1097.3904 | H6: 1569 | I6: Electrician installs a quick connect box so a rented trailer generator can plug in. Cost: NJ Office of Emergency Management, HMGP permissible uses list: quick connect or tap box about $100 per kW (x 100 kW). Rental: Vandalia Rental, 100 kW generator, $1,569 per week ($640 per day, $4,035 per month). Fuel: same as diesel row.
A7: Permanent generator, diesel | B7: 58333 | C7: Diesel | D7: 7.4 | E7: gallons | F7: 6.179 | G7: =D7*24*F7 -> 1097.3904 | H7: - | I7: Built-in generator with a fuel tank on site. Needs fuel deliveries in a long outage. Cost: NC Dept. of Public Safety, June 2019: more than $1.4 million for 24 generators (22 to 500 kW), about $58,333 each. 2019 dollars. NJ OEM range for a permanent generator: $450 to $650 per kW ($45,000 to $65,000 at 100 kW). Fuel: Herc Rentals, 100 kW at full load = 7.4 gal per hour. Price: EIA U.S. diesel retail, week of Oct 12, 2026.
A8: Permanent generator, natural gas | B8: =AVERAGE(39465/40,88500/80)*$B$21 -> 104643.75 | C8: Natural gas | D8: 1374 | E8: cubic feet | F8: =13.03/1000 -> 0.01303 | G8: =D8*24*F8 -> 429.67728 | H8: - | I8: Built-in generator on the gas line. No fuel deliveries, but only where piped gas exists. Cost: average cost per kW of two 2026 quotes, times kW per site: Santa Fe, TX, 40 kW gas unit for Runge Park Community Center, $39,465 (May 2026); Stow, OH, 80 kW natural gas unit for the community center, $88,500 (Aug 2026). Fuel: Generac QT100 manual, 1,374 cubic feet per hour at full load. Price: EIA U.S. commercial natural gas, July 2026, $13.03 per 1,000 cubic feet. The diesel cost above is in 2019 dollars, so part of the gap is price growth, not fuel type.
A9: Solar panels plus battery | B9: 589147 | C9: Sun | D9: 0 | E9: none | F9: 0 | G9: =D9*24*F9 -> 0 | H9: - | I9: Solar on the roof and a battery. No fuel, but less power than a 100 kW generator. Cost: Oregon Dept. of Energy grant, Feb 2026: Silver Falls Library District, 71 kW solar and 240 kWh battery, $589,147, so the library can act as an emergency center in outages. This is a grant amount; the full project cost may be higher. Best for critical loads only.
A12: 2. Other inputs
A13: Input | B13: Value | C13: Source and notes
A14: FEMA share of cost | B14: 0.75 | C14: FEMA Hazard Mitigation Grant Program share in the NC 2019 program (state paid 25%). Varies by program.
A15: Expected turnout at sites | B15: 0.25 | C15: PLACEHOLDER, not sourced. Share of people who would come to a site in a long outage. The county should set this.
A16: Power per person, low (watts) | B16: 275 | C16: Inogen At Home oxygen concentrator at 5 liters per minute (Inogen energy calculator).
A17: Power per person, high (watts) | B17: 550 | C17: Inogen says many concentrators use more than twice 275 W.
A18: Reach, rural (miles) | B18: 10 | C18: Assumption. Straight-line distance used by the rural site picker.
A19: Reach, urban (miles) | B19: 3 | C19: Assumption. People without a car can't travel far. Urban site counts come from power needs.
A20: Days in a long outage | B20: 3 | C20: PLANNING ASSUMPTION for the fuel and rental columns. Hurricane Beryl left 1.1 million Houston-area customers out 3 days later (Axios, Jul 11, 2024).
A21: Power per site (kW) | B21: 100 | C21: PLANNING ASSUMPTION, not sourced. One generator at a typical small public building. NC program sizes ranged 22 to 500 kW.
A24: 3. County plans | Q24: Cost for recommended sites, by generator type | U24: Cost for the high estimate, by generator type | Z24: Running cost, recommended sites
A25: County | B25: State | C25: FIPS | D25: Type | E25: Population (2020) | F25: Medicare members | G25: Rely on powered equipment | H25: Share of Medicare members | I25: Reach (mi) | J25: Expected at sites | K25: Power needed, low (kW) | L25: Power needed, high (kW) | M25: Sites from map (rural) | N25: Sites for full map coverage (rural) | O25: Recommended sites | P25: Sites, high estimate | Q25: Hookups only ($) | R25: Diesel ($) | S25: Natural gas ($) | T25: Solar + battery ($) | U25: Hookups only, high ($) | V25: Diesel, high ($) | W25: Natural gas, high ($) | X25: Solar + battery, high ($) | Y25: Local share if FEMA pays, diesel ($) | Z25: Hookups: rent for a long outage ($) | AA25: Diesel fuel for a long outage ($) | AB25: Natural gas for a long outage ($) | AC25: People in ZIP data (rural) | AD25: People reached, recommended sites (rural) | AE25: Coverage, recommended sites | AF25: How sites were counted
A26: Los Angeles County | B26: CA | C26: 06037 | D26: Urban | E26: 10014009 | F26: 1716142 | G26: 67311 | H26: =G26/F26 -> 0.039222279 | I26: =IF(D26="Rural",$B$18,$B$19) -> 3 | J26: =G26*$B$15 -> 16827.75 | K26: =J26*$B$16/1000 -> 4627.6313 | L26: =J26*$B$17/1000 -> 9255.2625 | O26: =IF(D26="Rural",MAX(M26,ROUNDUP(L26/$B$21,0)),ROUNDUP(K26/$B$21,0)) -> 47 | P26: =IF(D26="Rural",MAX(N26,ROUNDUP(L26/$B$21,0)),ROUNDUP(L26/$B$21,0)) -> 93 | Q26: =O26*$B$6 -> 470000 | R26: =O26*$B$7 -> 2741651 | S26: =O26*$B$8 -> 4918256.2 | T26: =O26*$B$9 -> 27689909 | U26: =P26*$B$6 -> 930000 | V26: =P26*$B$7 -> 5424969 | W26: =P26*$B$8 -> 9731868.8 | X26: =P26*$B$9 -> 54790671 | Y26: =R26*(1-$B$14) -> 685412.75 | Z26: =O26*($H$6*ROUNDUP($B$20/7,0)+$G$7*$B$20) -> 228475.05 | AA26: =O26*$G$7*$B$20 -> 154732.05 | AB26: =O26*$G$8*$B$20 -> 60584.496 | AE26: =IF(D26="Rural",AD26/AC26,"See Urban Site Plans") -> See Urban Site Plans | AF26: Power needs: expected people x watts / kW per site
A27: Cook County | B27: IL | C27: 17031 | D27: Urban | E27: 5275541 | F27: 880036 | G27: 33574 | H27: =G27/F27 -> 0.038150712 | I27: =IF(D27="Rural",$B$18,$B$19) -> 3 | J27: =G27*$B$15 -> 8393.5 | K27: =J27*$B$16/1000 -> 2308.2125 | L27: =J27*$B$17/1000 -> 4616.425 | O27: =IF(D27="Rural",MAX(M27,ROUNDUP(L27/$B$21,0)),ROUNDUP(K27/$B$21,0)) -> 24 | P27: =IF(D27="Rural",MAX(N27,ROUNDUP(L27/$B$21,0)),ROUNDUP(L27/$B$21,0)) -> 47 | Q27: =O27*$B$6 -> 240000 | R27: =O27*$B$7 -> 1399992 | S27: =O27*$B$8 -> 2511450 | T27: =O27*$B$9 -> 14139528 | U27: =P27*$B$6 -> 470000 | V27: =P27*$B$7 -> 2741651 | W27: =P27*$B$8 -> 4918256.2 | X27: =P27*$B$9 -> 27689909 | Y27: =R27*(1-$B$14) -> 349998 | Z27: =O27*($H$6*ROUNDUP($B$20/7,0)+$G$7*$B$20) -> 116668.11 | AA27: =O27*$G$7*$B$20 -> 79012.109 | AB27: =O27*$G$8*$B$20 -> 30936.764 | AE27: =IF(D27="Rural",AD27/AC27,"See Urban Site Plans") -> See Urban Site Plans | AF27: Power needs: expected people x watts / kW per site
A28: Harris County | B28: TX | C28: 48201 | D28: Urban | E28: 4731145 | F28: 672080 | G28: 28811 | H28: =G28/F28 -> 0.042868409 | I28: =IF(D28="Rural",$B$18,$B$19) -> 3 | J28: =G28*$B$15 -> 7202.75 | K28: =J28*$B$16/1000 -> 1980.7562 | L28: =J28*$B$17/1000 -> 3961.5125 | O28: =IF(D28="Rural",MAX(M28,ROUNDUP(L28/$B$21,0)),ROUNDUP(K28/$B$21,0)) -> 20 | P28: =IF(D28="Rural",MAX(N28,ROUNDUP(L28/$B$21,0)),ROUNDUP(L28/$B$21,0)) -> 40 | Q28: =O28*$B$6 -> 200000 | R28: =O28*$B$7 -> 1166660 | S28: =O28*$B$8 -> 2092875 | T28: =O28*$B$9 -> 11782940 | U28: =P28*$B$6 -> 400000 | V28: =P28*$B$7 -> 2333320 | W28: =P28*$B$8 -> 4185750 | X28: =P28*$B$9 -> 23565880 | Y28: =R28*(1-$B$14) -> 291665 | Z28: =O28*($H$6*ROUNDUP($B$20/7,0)+$G$7*$B$20) -> 97223.424 | AA28: =O28*$G$7*$B$20 -> 65843.424 | AB28: =O28*$G$8*$B$20 -> 25780.637 | AE28: =IF(D28="Rural",AD28/AC28,"See Urban Site Plans") -> See Urban Site Plans | AF28: Power needs: expected people x watts / kW per site
A29: Maricopa County | B29: AZ | C29: 04013 | D29: Urban | E29: 4420568 | F29: 817022 | G29: 32883 | H29: =G29/F29 -> 0.040247386 | I29: =IF(D29="Rural",$B$18,$B$19) -> 3 | J29: =G29*$B$15 -> 8220.75 | K29: =J29*$B$16/1000 -> 2260.7063 | L29: =J29*$B$17/1000 -> 4521.4125 | O29: =IF(D29="Rural",MAX(M29,ROUNDUP(L29/$B$21,0)),ROUNDUP(K29/$B$21,0)) -> 23 | P29: =IF(D29="Rural",MAX(N29,ROUNDUP(L29/$B$21,0)),ROUNDUP(L29/$B$21,0)) -> 46 | Q29: =O29*$B$6 -> 230000 | R29: =O29*$B$7 -> 1341659 | S29: =O29*$B$8 -> 2406806.2 | T29: =O29*$B$9 -> 13550381 | U29: =P29*$B$6 -> 460000 | V29: =P29*$B$7 -> 2683318 | W29: =P29*$B$8 -> 4813612.5 | X29: =P29*$B$9 -> 27100762 | Y29: =R29*(1-$B$14) -> 335414.75 | Z29: =O29*($H$6*ROUNDUP($B$20/7,0)+$G$7*$B$20) -> 111806.94 | AA29: =O29*$G$7*$B$20 -> 75719.938 | AB29: =O29*$G$8*$B$20 -> 29647.732 | AE29: =IF(D29="Rural",AD29/AC29,"See Urban Site Plans") -> See Urban Site Plans | AF29: Power needs: expected people x watts / kW per site
A30: Miami-Dade County | B30: FL | C30: 12086 | D30: Urban | E30: 2701767 | F30: 525034 | G30: 23346 | H30: =G30/F30 -> 0.044465692 | I30: =IF(D30="Rural",$B$18,$B$19) -> 3 | J30: =G30*$B$15 -> 5836.5 | K30: =J30*$B$16/1000 -> 1605.0375 | L30: =J30*$B$17/1000 -> 3210.075 | O30: =IF(D30="Rural",MAX(M30,ROUNDUP(L30/$B$21,0)),ROUNDUP(K30/$B$21,0)) -> 17 | P30: =IF(D30="Rural",MAX(N30,ROUNDUP(L30/$B$21,0)),ROUNDUP(L30/$B$21,0)) -> 33 | Q30: =O30*$B$6 -> 170000 | R30: =O30*$B$7 -> 991661 | S30: =O30*$B$8 -> 1778943.8 | T30: =O30*$B$9 -> 10015499 | U30: =P30*$B$6 -> 330000 | V30: =P30*$B$7 -> 1924989 | W30: =P30*$B$8 -> 3453243.8 | X30: =P30*$B$9 -> 19441851 | Y30: =R30*(1-$B$14) -> 247915.25 | Z30: =O30*($H$6*ROUNDUP($B$20/7,0)+$G$7*$B$20) -> 82639.91 | AA30: =O30*$G$7*$B$20 -> 55966.91 | AB30: =O30*$G$8*$B$20 -> 21913.541 | AE30: =IF(D30="Rural",AD30/AC30,"See Urban Site Plans") -> See Urban Site Plans | AF30: Power needs: expected people x watts / kW per site
A31: Athens County | B31: OH | C31: 39009 | D31: Rural | E31: 62431 | F31: 12713 | G31: 845 | H31: =G31/F31 -> 0.066467396 | I31: =IF(D31="Rural",$B$18,$B$19) -> 10 | J31: =G31*$B$15 -> 211.25 | K31: =J31*$B$16/1000 -> 58.09375 | L31: =J31*$B$17/1000 -> 116.1875 | M31: 3 | N31: 4 | O31: =IF(D31="Rural",MAX(M31,ROUNDUP(L31/$B$21,0)),ROUNDUP(K31/$B$21,0)) -> 3 | P31: =IF(D31="Rural",MAX(N31,ROUNDUP(L31/$B$21,0)),ROUNDUP(L31/$B$21,0)) -> 4 | Q31: =O31*$B$6 -> 30000 | R31: =O31*$B$7 -> 174999 | S31: =O31*$B$8 -> 313931.25 | T31: =O31*$B$9 -> 1767441 | U31: =P31*$B$6 -> 40000 | V31: =P31*$B$7 -> 233332 | W31: =P31*$B$8 -> 418575 | X31: =P31*$B$9 -> 2356588 | Y31: =R31*(1-$B$14) -> 43749.75 | Z31: =O31*($H$6*ROUNDUP($B$20/7,0)+$G$7*$B$20) -> 14583.514 | AA31: =O31*$G$7*$B$20 -> 9876.5136 | AB31: =O31*$G$8*$B$20 -> 3867.0955 | AC31: 829 | AD31: 805 | AE31: =IF(D31="Rural",AD31/AC31,"See Urban Site Plans") -> 0.97104946 | AF31: Site picker on 7 real library branches, 10 mi. Full coverage adds a site near Amesville.
A32: Harlan County | B32: KY | C32: 21095 | D32: Rural | E32: 26831 | F32: 6953 | G32: 875 | H32: =G32/F32 -> 0.12584496 | I32: =IF(D32="Rural",$B$18,$B$19) -> 10 | J32: =G32*$B$15 -> 218.75 | K32: =J32*$B$16/1000 -> 60.15625 | L32: =J32*$B$17/1000 -> 120.3125 | M32: 2 | N32: 4 | O32: =IF(D32="Rural",MAX(M32,ROUNDUP(L32/$B$21,0)),ROUNDUP(K32/$B$21,0)) -> 2 | P32: =IF(D32="Rural",MAX(N32,ROUNDUP(L32/$B$21,0)),ROUNDUP(L32/$B$21,0)) -> 4 | Q32: =O32*$B$6 -> 20000 | R32: =O32*$B$7 -> 116666 | S32: =O32*$B$8 -> 209287.5 | T32: =O32*$B$9 -> 1178294 | U32: =P32*$B$6 -> 40000 | V32: =P32*$B$7 -> 233332 | W32: =P32*$B$8 -> 418575 | X32: =P32*$B$9 -> 2356588 | Y32: =R32*(1-$B$14) -> 29166.5 | Z32: =O32*($H$6*ROUNDUP($B$20/7,0)+$G$7*$B$20) -> 9722.3424 | AA32: =O32*$G$7*$B$20 -> 6584.3424 | AB32: =O32*$G$8*$B$20 -> 2578.0637 | AC32: 861 | AD32: 833 | AE32: =IF(D32="Rural",AD32/AC32,"See Urban Site Plans") -> 0.96747967 | AF32: Site picker on ZIP code centers (town centers), 10 mi
A33: Coos County | B33: NH | C33: 33007 | D33: Rural | E33: 31268 | F33: 11023 | G33: 466 | H33: =G33/F33 -> 0.042275243 | I33: =IF(D33="Rural",$B$18,$B$19) -> 10 | J33: =G33*$B$15 -> 116.5 | K33: =J33*$B$16/1000 -> 32.0375 | L33: =J33*$B$17/1000 -> 64.075 | M33: 5 | N33: 8 | O33: =IF(D33="Rural",MAX(M33,ROUNDUP(L33/$B$21,0)),ROUNDUP(K33/$B$21,0)) -> 5 | P33: =IF(D33="Rural",MAX(N33,ROUNDUP(L33/$B$21,0)),ROUNDUP(L33/$B$21,0)) -> 8 | Q33: =O33*$B$6 -> 50000 | R33: =O33*$B$7 -> 291665 | S33: =O33*$B$8 -> 523218.75 | T33: =O33*$B$9 -> 2945735 | U33: =P33*$B$6 -> 80000 | V33: =P33*$B$7 -> 466664 | W33: =P33*$B$8 -> 837150 | X33: =P33*$B$9 -> 4713176 | Y33: =R33*(1-$B$14) -> 72916.25 | Z33: =O33*($H$6*ROUNDUP($B$20/7,0)+$G$7*$B$20) -> 24305.856 | AA33: =O33*$G$7*$B$20 -> 16460.856 | AB33: =O33*$G$8*$B$20 -> 6445.1592 | AC33: 477 | AD33: 438 | AE33: =IF(D33="Rural",AD33/AC33,"See Urban Site Plans") -> 0.91823899 | AF33: Site picker on ZIP code centers (town centers), 10 mi
A34: Big Horn County | B34: MT | C34: 30003 | D34: Rural | E34: 13124 | F34: 2101 | G34: 223 | H34: =G34/F34 -> 0.10613993 | I34: =IF(D34="Rural",$B$18,$B$19) -> 10 | J34: =G34*$B$15 -> 55.75 | K34: =J34*$B$16/1000 -> 15.33125 | L34: =J34*$B$17/1000 -> 30.6625 | M34: 8 | N34: 10 | O34: =IF(D34="Rural",MAX(M34,ROUNDUP(L34/$B$21,0)),ROUNDUP(K34/$B$21,0)) -> 8 | P34: =IF(D34="Rural",MAX(N34,ROUNDUP(L34/$B$21,0)),ROUNDUP(L34/$B$21,0)) -> 10 | Q34: =O34*$B$6 -> 80000 | R34: =O34*$B$7 -> 466664 | S34: =O34*$B$8 -> 837150 | T34: =O34*$B$9 -> 4713176 | U34: =P34*$B$6 -> 100000 | V34: =P34*$B$7 -> 583330 | W34: =P34*$B$8 -> 1046437.5 | X34: =P34*$B$9 -> 5891470 | Y34: =R34*(1-$B$14) -> 116666 | Z34: =O34*($H$6*ROUNDUP($B$20/7,0)+$G$7*$B$20) -> 38889.37 | AA34: =O34*$G$7*$B$20 -> 26337.37 | AB34: =O34*$G$8*$B$20 -> 10312.255 | AC34: 223 | AD34: 201 | AE34: =IF(D34="Rural",AD34/AC34,"See Urban Site Plans") -> 0.90134529 | AF34: Site picker on ZIP code centers (town centers), 10 mi
A35: Sunflower County | B35: MS | C35: 28133 | D35: Rural | E35: 25971 | F35: 4842 | G35: 359 | H35: =G35/F35 -> 0.074142916 | I35: =IF(D35="Rural",$B$18,$B$19) -> 10 | J35: =G35*$B$15 -> 89.75 | K35: =J35*$B$16/1000 -> 24.68125 | L35: =J35*$B$17/1000 -> 49.3625 | M35: 3 | N35: 4 | O35: =IF(D35="Rural",MAX(M35,ROUNDUP(L35/$B$21,0)),ROUNDUP(K35/$B$21,0)) -> 3 | P35: =IF(D35="Rural",MAX(N35,ROUNDUP(L35/$B$21,0)),ROUNDUP(L35/$B$21,0)) -> 4 | Q35: =O35*$B$6 -> 30000 | R35: =O35*$B$7 -> 174999 | S35: =O35*$B$8 -> 313931.25 | T35: =O35*$B$9 -> 1767441 | U35: =P35*$B$6 -> 40000 | V35: =P35*$B$7 -> 233332 | W35: =P35*$B$8 -> 418575 | X35: =P35*$B$9 -> 2356588 | Y35: =R35*(1-$B$14) -> 43749.75 | Z35: =O35*($H$6*ROUNDUP($B$20/7,0)+$G$7*$B$20) -> 14583.514 | AA35: =O35*$G$7*$B$20 -> 9876.5136 | AB35: =O35*$G$8*$B$20 -> 3867.0955 | AC35: 359 | AD35: 345 | AE35: =IF(D35="Rural",AD35/AC35,"See Urban Site Plans") -> 0.96100279 | AF35: Site picker on ZIP code centers (town centers), 10 mi
A37: Urban total | E37: =SUMIFS(E26:E35,$D$26:$D$35,"Urban") -> 27143030 | G37: =SUMIFS(G26:G35,$D$26:$D$35,"Urban") -> 185925 | O37: =SUMIFS(O26:O35,$D$26:$D$35,"Urban") -> 131 | P37: =SUMIFS(P26:P35,$D$26:$D$35,"Urban") -> 259 | Q37: =SUMIFS(Q26:Q35,$D$26:$D$35,"Urban") -> 1310000 | R37: =SUMIFS(R26:R35,$D$26:$D$35,"Urban") -> 7641623 | S37: =SUMIFS(S26:S35,$D$26:$D$35,"Urban") -> 13708331 | T37: =SUMIFS(T26:T35,$D$26:$D$35,"Urban") -> 77178257 | U37: =SUMIFS(U26:U35,$D$26:$D$35,"Urban") -> 2590000 | V37: =SUMIFS(V26:V35,$D$26:$D$35,"Urban") -> 15108247 | ... AB37: =SUMIFS(AB26:AB35,$D$26:$D$35,"Urban") -> 168863.17
A38: Rural total | E38: =SUMIFS(E26:E35,$D$26:$D$35,"Rural") -> 159625 | G38: =SUMIFS(G26:G35,$D$26:$D$35,"Rural") -> 2768 | O38: =SUMIFS(O26:O35,$D$26:$D$35,"Rural") -> 21 | P38: =SUMIFS(P26:P35,$D$26:$D$35,"Rural") -> 30 | Q38: =SUMIFS(Q26:Q35,$D$26:$D$35,"Rural") -> 210000 | R38: =SUMIFS(R26:R35,$D$26:$D$35,"Rural") -> 1224993 | S38: =SUMIFS(S26:S35,$D$26:$D$35,"Rural") -> 2197518.8 | T38: =SUMIFS(T26:T35,$D$26:$D$35,"Rural") -> 12372087 | U38: =SUMIFS(U26:U35,$D$26:$D$35,"Rural") -> 300000 | V38: =SUMIFS(V26:V35,$D$26:$D$35,"Rural") -> 1749990 | ... AB38: =SUMIFS(AB26:AB35,$D$26:$D$35,"Rural") -> 27069.669
A39: All 10 counties | E39: =SUM(E26:E35) -> 27302655 | G39: =SUM(G26:G35) -> 188693 | O39: =SUM(O26:O35) -> 152 | P39: =SUM(P26:P35) -> 289 | Q39: =SUM(Q26:Q35) -> 1520000 | R39: =SUM(R26:R35) -> 8866616 | S39: =SUM(S26:S35) -> 15905850 | T39: =SUM(T26:T35) -> 89550344 | U39: =SUM(U26:U35) -> 2890000 | V39: =SUM(V26:V35) -> 16858237 | ... AB39: =SUM(AB26:AB35) -> 195932.84
A41: How to read this sheet
A42: Recommended sites: rural = the larger of (sites to reach at least 90% of people in the ZIP data, from the site picker) and (sites needed for power at the high wattage). Urban = sites for power at the low wattage.
A43: Sites, high estimate: rural = sites to reach everyone in the ZIP data. Urban = sites for power at the high wattage.
A44: Each budget = number of sites x cost per site for that generator type (block 1). Running costs = sites x cost per day x days in a long outage (block 2).
A45: Hookups are the cheapest to set up but the county pays rent and fuel every outage. Natural gas needs no fuel deliveries but only works where there is a gas line, which many rural areas lack.
A46: Solar + battery has no fuel cost but gives less power than a 100 kW generator, so it suits critical loads (oxygen, medicine fridge, phone charging).
A47: People counts are Medicare members only (HHS emPOWER, county layer, updated Aug 2026). ZIP data hides counts of 1 to 10 as 11, so ZIP totals can differ from county totals.
...

Sheet Rural Site Plans
A1: Rural site plans from the site picker
A2: Each row adds the site that reaches the most people not yet covered (10 mile straight-line reach). Best possible = every combination checked, up to 6 sites. Cost columns = total for all sites so far.
A4: County | B4: Site # | C4: Site | D4: ZIP | E4: New people reached | F4: Total reached | G4: People in ZIP data | H4: Share reached | I4: Best possible with this many | J4: Site picker vs best | K4: Hookups only ($) | L4: Diesel ($) | M4: Natural gas ($) | N4: Solar + battery ($)
A5: Athens County, OH | B5: 1 | C5: Chauncey Public Library | D5: 45719 | E5: 597 | F5: 597 | G5: 829 | H5: =F5/G5 -> 0.72014475 | I5: 597 | J5: =F5/I5 -> 1 | K5: =B5*'County Plans'!$B$6 -> 10000 | L5: =B5*'County Plans'!$B$7 -> 58333 | M5: =B5*'County Plans'!$B$8 -> 104643.75 | N5: =B5*'County Plans'!$B$9 -> 589147
A6: Athens County, OH | B6: 2 | C6: Coolville Public Library | D6: 45723 | E6: 107 | F6: 704 | G6: 829 | H6: =F6/G6 -> 0.84921592 | I6: 704 | J6: =F6/I6 -> 1 | K6: =B6*'County Plans'!$B$6 -> 20000 | L6: =B6*'County Plans'!$B$7 -> 116666 | M6: =B6*'County Plans'!$B$8 -> 209287.5 | N6: =B6*'County Plans'!$B$9 -> 1178294
A7: Athens County, OH | B7: 3 | C7: Wells (Albany) Public Library | D7: 45710 | E7: 101 | F7: 805 | G7: 829 | H7: =F7/G7 -> 0.97104946 | I7: 805 | J7: =F7/I7 -> 1 | K7: =B7*'County Plans'!$B$6 -> 30000 | L7: =B7*'County Plans'!$B$7 -> 174999 | M7: =B7*'County Plans'!$B$8 -> 313931.25 | N7: =B7*'County Plans'!$B$9 -> 1767441
A8: Harlan County, KY | B8: 1 | C8: Public building near Coalgood | D8: 40818 | E8: 638 | F8: 638 | G8: 861 | H8: =F8/G8 -> 0.74099884 | I8: 638 | J8: =IF(ISNUMBER(I8),F8/I8,"") -> 1 | K8: =B8*'County Plans'!$B$6 -> 10000 | L8: =B8*'County Plans'!$B$7 -> 58333 | M8: =B8*'County Plans'!$B$8 -> 104643.75 | N8: =B8*'County Plans'!$B$9 -> 589147
A9: Harlan County, KY | B9: 2 | C9: Public building near Lynch | D9: 40855 | E9: 195 | F9: 833 | G9: 861 | H9: =F9/G9 -> 0.96747967 | I9: 833 | J9: =IF(ISNUMBER(I9),F9/I9,"") -> 1 | K9: =B9*'County Plans'!$B$6 -> 20000 | L9: =B9*'County Plans'!$B$7 -> 116666 | M9: =B9*'County Plans'!$B$8 -> 209287.5 | N9: =B9*'County Plans'!$B$9 -> 1178294
A10: Harlan County, KY | B10: 3 | C10: Public building near Coldiron | D10: 40819 | E10: 17 | F10: 850 | G10: 861 | H10: =F10/G10 -> 0.98722416 | I10: 861 | J10: =IF(ISNUMBER(I10),F10/I10,"") -> 0.98722416 | K10: =B10*'County Plans'!$B$6 -> 30000 | L10: =B10*'County Plans'!$B$7 -> 174999 | M10: =B10*'County Plans'!$B$8 -> 313931.25 | N10: =B10*'County Plans'!$B$9 -> 1767441
A11: Harlan County, KY | B11: 4 | C11: Public building near Big Laurel | D11: 40808 | E11: 11 | F11: 861 | G11: 861 | H11: =F11/G11 -> 1 | I11: 861 | J11: =IF(ISNUMBER(I11),F11/I11,"") -> 1 | K11: =B11*'County Plans'!$B$6 -> 40000 | L11: =B11*'County Plans'!$B$7 -> 233332 | M11: =B11*'County Plans'!$B$8 -> 418575 | N11: =B11*'County Plans'!$B$9 -> 2356588
A12: Coos County, NH | B12: 1 | C12: Public building near Berlin | D12: 03570 | E12: 224 | F12: 224 | G12: 477 | H12: =F12/G12 -> 0.46960168 | I12: 224 | J12: =IF(ISNUMBER(I12),F12/I12,"") -> 1 | K12: =B12*'County Plans'!$B$6 -> 10000 | L12: =B12*'County Plans'!$B$7 -> 58333 | M12: =B12*'County Plans'!$B$8 -> 104643.75 | N12: =B12*'County Plans'!$B$9 -> 589147
A13: Coos County, NH | B13: 2 | C13: Public building near Lancaster | D13: 03584 | E13: 122 | F13: 346 | G13: 477 | H13: =F13/G13 -> 0.72536688 | I13: 346 | J13: =IF(ISNUMBER(I13),F13/I13,"") -> 1 | K13: =B13*'County Plans'!$B$6 -> 20000 | L13: =B13*'County Plans'!$B$7 -> 116666 | M13: =B13*'County Plans'!$B$8 -> 209287.5 | N13: =B13*'County Plans'!$B$9 -> 1178294
A14: Coos County, NH | B14: 3 | C14: Public building near Colebrook | D14: 03576 | E14: 47 | F14: 393 | G14: 477 | H14: =F14/G14 -> 0.82389937 | I14: 393 | J14: =IF(ISNUMBER(I14),F14/I14,"") -> 1 | K14: =B14*'County Plans'!$B$6 -> 30000 | L14: =B14*'County Plans'!$B$7 -> 174999 | M14: =B14*'County Plans'!$B$8 -> 313931.25 | N14: =B14*'County Plans'!$B$9 -> 1767441
A15: Coos County, NH | B15: 4 | C15: Public building near Twin Mountain | D15: 03595 | E15: 27 | F15: 420 | G15: 477 | H15: =F15/G15 -> 0.88050314 | I15: 437 | J15: =IF(ISNUMBER(I15),F15/I15,"") -> 0.9610984 | K15: =B15*'County Plans'!$B$6 -> 40000 | L15: =B15*'County Plans'!$B$7 -> 233332 | M15: =B15*'County Plans'!$B$8 -> 418575 | N15: =B15*'County Plans'!$B$9 -> 2356588
A16: Coos County, NH | B16: 5 | C16: Public building near Pittsburg | D16: 03592 | E16: 18 | F16: 438 | G16: 477 | H16: =F16/G16 -> 0.91823899 | I16: 455 | J16: =IF(ISNUMBER(I16),F16/I16,"") -> 0.96263736 | K16: =B16*'County Plans'!$B$6 -> 50000 | L16: =B16*'County Plans'!$B$7 -> 291665 | M16: =B16*'County Plans'!$B$8 -> 523218.75 | N16: =B16*'County Plans'!$B$9 -> 2945735
A17: Coos County, NH | B17: 6 | C17: Public building near Groveton | D17: 03582 | E17: 17 | F17: 455 | G17: 477 | H17: =F17/G17 -> 0.95387841 | I17: 466 | J17: =IF(ISNUMBER(I17),F17/I17,"") -> 0.97639485 | K17: =B17*'County Plans'!$B$6 -> 60000 | L17: =B17*'County Plans'!$B$7 -> 349998 | M17: =B17*'County Plans'!$B$8 -> 627862.5 | N17: =B17*'County Plans'!$B$9 -> 3534882
A18: Coos County, NH | B18: 7 | C18: Public building near Errol | D18: 03579 | E18: 11 | F18: 466 | G18: 477 | H18: =F18/G18 -> 0.9769392 | I18: Not checked | J18: =IF(ISNUMBER(I18),F18/I18,"") | K18: =B18*'County Plans'!$B$6 -> 70000 | L18: =B18*'County Plans'!$B$7 -> 408331 | M18: =B18*'County Plans'!$B$8 -> 732506.25 | N18: =B18*'County Plans'!$B$9 -> 4124029
A19: Coos County, NH | B19: 8 | C19: Public building near Jackson | D19: 03846 | E19: 11 | F19: 477 | G19: 477 | H19: =F19/G19 -> 1 | I19: Not checked | J19: =IF(ISNUMBER(I19),F19/I19,"") | K19: =B19*'County Plans'!$B$6 -> 80000 | L19: =B19*'County Plans'!$B$7 -> 466664 | M19: =B19*'County Plans'!$B$8 -> 837150 | N19: =B19*'County Plans'!$B$9 -> 4713176
A20: Big Horn County, MT | B20: 1 | C20: Public building near Hardin | D20: 59034 | E20: 93 | F20: 93 | G20: 223 | H20: =F20/G20 -> 0.41704036 | I20: 93 | J20: =IF(ISNUMBER(I20),F20/I20,"") -> 1 | K20: =B20*'County Plans'!$B$6 -> 10000 | L20: =B20*'County Plans'!$B$7 -> 58333 | M20: =B20*'County Plans'!$B$8 -> 104643.75 | N20: =B20*'County Plans'!$B$9 -> 589147
A21: Big Horn County, MT | B21: 2 | C21: Public building near Crow Agency | D21: 59022 | E21: 32 | F21: 125 | G21: 223 | H21: =F21/G21 -> 0.56053812 | I21: 125 | J21: =IF(ISNUMBER(I21),F21/I21,"") -> 1 | K21: =B21*'County Plans'!$B$6 -> 20000 | L21: =B21*'County Plans'!$B$7 -> 116666 | M21: =B21*'County Plans'!$B$8 -> 209287.5 | N21: =B21*'County Plans'!$B$9 -> 1178294
A22: Big Horn County, MT | B22: 3 | C22: Public building near Lodge Grass | D22: 59050 | E22: 20 | F22: 145 | G22: 223 | H22: =F22/G22 -> 0.65022422 | I22: 145 | J22: =IF(ISNUMBER(I22),F22/I22,"") -> 1 | K22: =B22*'County Plans'!$B$6 -> 30000 | L22: =B22*'County Plans'!$B$7 -> 174999 | M22: =B22*'County Plans'!$B$8 -> 313931.25 | N22: =B22*'County Plans'!$B$9 -> 1767441
A23: Big Horn County, MT | B23: 4 | C23: Public building near Busby | D23: 59016 | E23: 12 | F23: 157 | G23: 223 | H23: =F23/G23 -> 0.70403587 | I23: 157 | J23: =IF(ISNUMBER(I23),F23/I23,"") -> 1 | K23: =B23*'County Plans'!$B$6 -> 40000 | L23: =B23*'County Plans'!$B$7 -> 233332 | M23: =B23*'County Plans'!$B$8 -> 418575 | N23: =B23*'County Plans'!$B$9 -> 2356588
A24: Big Horn County, MT | B24: 5 | C24: Public building near Pryor | D24: 59066 | E24: 11 | F24: 168 | G24: 223 | H24: =F24/G24 -> 0.75336323 | I24: 168 | J24: =IF(ISNUMBER(I24),F24/I24,"") -> 1 | K24: =B24*'County Plans'!$B$6 -> 50000 | L24: =B24*'County Plans'!$B$7 -> 291665 | M24: =B24*'County Plans'!$B$8 -> 523218.75 | N24: =B24*'County Plans'!$B$9 -> 2945735
A25: Big Horn County, MT | B25: 6 | C25: Public building near Garryowen | D25: 59031 | E25: 11 | F25: 179 | G25: 223 | H25: =F25/G25 -> 0.80269058 | I25: 179 | J25: =IF(ISNUMBER(I25),F25/I25,"") -> 1 | K25: =B25*'County Plans'!$B$6 -> 60000 | L25: =B25*'County Plans'!$B$7 -> 349998 | M25: =B25*'County Plans'!$B$8 -> 627862.5 | N25: =B25*'County Plans'!$B$9 -> 3534882
A26: Big Horn County, MT | B26: 7 | C26: Public building near Fort Smith | D26: 59035 | E26: 11 | F26: 190 | G26: 223 | H26: =F26/G26 -> 0.85201794 | I26: Not checked | J26: =IF(ISNUMBER(I26),F26/I26,"") | K26: =B26*'County Plans'!$B$6 -> 70000 | L26: =B26*'County Plans'!$B$7 -> 408331 | M26: =B26*'County Plans'!$B$8 -> 732506.25 | N26: =B26*'County Plans'!$B$9 -> 4124029
A27: Big Horn County, MT | B27: 8 | C27: Public building near Saint Xavier | D27: 59075 | E27: 11 | F27: 201 | G27: 223 | H27: =F27/G27 -> 0.90134529 | I27: Not checked | J27: =IF(ISNUMBER(I27),F27/I27,"") | K27: =B27*'County Plans'!$B$6 -> 80000 | L27: =B27*'County Plans'!$B$7 -> 466664 | M27: =B27*'County Plans'!$B$8 -> 837150 | N27: =B27*'County Plans'!$B$9 -> 4713176
A28: Big Horn County, MT | B28: 9 | C28: Public building near Wyola | D28: 59089 | E28: 11 | F28: 212 | G28: 223 | H28: =F28/G28 -> 0.95067265 | I28: Not checked | J28: =IF(ISNUMBER(I28),F28/I28,"") | K28: =B28*'County Plans'!$B$6 -> 90000 | L28: =B28*'County Plans'!$B$7 -> 524997 | M28: =B28*'County Plans'!$B$8 -> 941793.75 | N28: =B28*'County Plans'!$B$9 -> 5302323
A29: Big Horn County, MT | B29: 10 | C29: Public building near Decker | D29: 59025 | E29: 11 | F29: 223 | G29: 223 | H29: =F29/G29 -> 1 | I29: Not checked | J29: =IF(ISNUMBER(I29),F29/I29,"") | K29: =B29*'County Plans'!$B$6 -> 100000 | L29: =B29*'County Plans'!$B$7 -> 583330 | M29: =B29*'County Plans'!$B$8 -> 1046437.5 | N29: =B29*'County Plans'!$B$9 -> 5891470
A30: Sunflower County, MS | B30: 1 | C30: Public building near Sunflower | D30: 38778 | E30: 250 | F30: 250 | G30: 359 | H30: =F30/G30 -> 0.69637883 | I30: 250 | J30: =IF(ISNUMBER(I30),F30/I30,"") -> 1 | K30: =B30*'County Plans'!$B$6 -> 10000 | L30: =B30*'County Plans'!$B$7 -> 58333 | M30: =B30*'County Plans'!$B$8 -> 104643.75 | N30: =B30*'County Plans'!$B$9 -> 589147
A31: Sunflower County, MS | B31: 2 | C31: Public building near Doddsville | D31: 38736 | E31: 53 | F31: 303 | G31: 359 | H31: =F31/G31 -> 0.84401114 | I31: 303 | J31: =IF(ISNUMBER(I31),F31/I31,"") -> 1 | K31: =B31*'County Plans'!$B$6 -> 20000 | L31: =B31*'County Plans'!$B$7 -> 116666 | M31: =B31*'County Plans'!$B$8 -> 209287.5 | N31: =B31*'County Plans'!$B$9 -> 1178294
A32: Sunflower County, MS | B32: 3 | C32: Public building near Drew | D32: 38737 | E32: 42 | F32: 345 | G32: 359 | H32: =F32/G32 -> 0.96100279 | I32: 345 | J32: =IF(ISNUMBER(I32),F32/I32,"") -> 1 | K32: =B32*'County Plans'!$B$6 -> 30000 | L32: =B32*'County Plans'!$B$7 -> 174999 | M32: =B32*'County Plans'!$B$8 -> 313931.25 | N32: =B32*'County Plans'!$B$9 -> 1767441
A33: Sunflower County, MS | B33: 4 | C33: Public building near Inverness | D33: 38753 | E33: 14 | F33: 359 | G33: 359 | H33: =F33/G33 -> 1 | I33: 359 | J33: =IF(ISNUMBER(I33),F33/I33,"") -> 1 | K33: =B33*'County Plans'!$B$6 -> 40000 | L33: =B33*'County Plans'!$B$7 -> 233332 | M33: =B33*'County Plans'!$B$8 -> 418575 | N33: =B33*'County Plans'!$B$9 -> 2356588
A35: Athens sites are real library branches (Athens County Public Libraries, myacpl.org), placed at their ZIP center. Amesville (ZIP 45711, 24 people) is not within 10 miles of any library.
A36: Sites for Harlan, Coos, Big Horn and Sunflower are town centers (ZIP code centers), not specific buildings yet.
A37: Costs per site come from block 1 on the County Plans sheet.

Sheet Urban Site Plans
A1: Urban site plans: start with the 10 ZIP codes that have the most people at risk
A2: Big counties are planned one area at a time. Each row sizes the sites for one ZIP code from its power needs (people x turnout x watts / kW per site). Pick a library, school, or community center inside each ZIP.
A4: County | B4: Rank | C4: ZIP | D4: Area | E4: Rely on powered equipment | F4: Share of county total | G4: Expected at sites | H4: Power needed, low (kW) | I4: Power needed, high (kW) | J4: Sites needed | K4: Sites, high estimate | L4: Hookups only ($) | M4: Diesel ($) | N4: Natural gas ($) | O4: Solar + battery ($)
A5: Los Angeles County, CA | B5: 1 | C5: 93535 | D5: Lancaster | E5: 824 | F5: =E5/'County Plans'!$G$26 -> 0.012241684 | G5: =E5*'County Plans'!$B$15 -> 206 | H5: =G5*'County Plans'!$B$16/1000 -> 56.65 | I5: =G5*'County Plans'!$B$17/1000 -> 113.3 | J5: =ROUNDUP(H5/'County Plans'!$B$21,0) -> 1 | K5: =ROUNDUP(I5/'County Plans'!$B$21,0) -> 2 | L5: =J5*'County Plans'!$B$6 -> 10000 | M5: =J5*'County Plans'!$B$7 -> 58333 | N5: =J5*'County Plans'!$B$8 -> 104643.75 | O5: =J5*'County Plans'!$B$9 -> 589147
A6: Los Angeles County, CA | B6: 2 | C6: 93536 | D6: Lancaster | E6: 771 | F6: =E6/'County Plans'!$G$26 -> 0.011454294 | G6: =E6*'County Plans'!$B$15 -> 192.75 | H6: =G6*'County Plans'!$B$16/1000 -> 53.00625 | I6: =G6*'County Plans'!$B$17/1000 -> 106.0125 | J6: =ROUNDUP(H6/'County Plans'!$B$21,0) -> 1 | K6: =ROUNDUP(I6/'County Plans'!$B$21,0) -> 2 | L6: =J6*'County Plans'!$B$6 -> 10000 | M6: =J6*'County Plans'!$B$7 -> 58333 | N6: =J6*'County Plans'!$B$8 -> 104643.75 | O6: =J6*'County Plans'!$B$9 -> 589147
A7: Los Angeles County, CA | B7: 3 | C7: 90650 | D7: Norwalk | E7: 723 | F7: =E7/'County Plans'!$G$26 -> 0.010741186 | G7: =E7*'County Plans'!$B$15 -> 180.75 | H7: =G7*'County Plans'!$B$16/1000 -> 49.70625 | I7: =G7*'County Plans'!$B$17/1000 -> 99.4125 | J7: =ROUNDUP(H7/'County Plans'!$B$21,0) -> 1 | K7: =ROUNDUP(I7/'County Plans'!$B$21,0) -> 1 | L7: =J7*'County Plans'!$B$6 -> 10000 | M7: =J7*'County Plans'!$B$7 -> 58333 | N7: =J7*'County Plans'!$B$8 -> 104643.75 | O7: =J7*'County Plans'!$B$9 -> 589147
A8: Los Angeles County, CA | B8: 4 | C8: 91342 | D8: Sylmar | E8: 700 | F8: =E8/'County Plans'!$G$26 -> 0.010399489 | G8: =E8*'County Plans'!$B$15 -> 175 | H8: =G8*'County Plans'!$B$16/1000 -> 48.125 | I8: =G8*'County Plans'!$B$17/1000 -> 96.25 | J8: =ROUNDUP(H8/'County Plans'!$B$21,0) -> 1 | K8: =ROUNDUP(I8/'County Plans'!$B$21,0) -> 1 | L8: =J8*'County Plans'!$B$6 -> 10000 | M8: =J8*'County Plans'!$B$7 -> 58333 | N8: =J8*'County Plans'!$B$8 -> 104643.75 | O8: =J8*'County Plans'!$B$9 -> 589147
A9: Los Angeles County, CA | B9: 5 | C9: 93550 | D9: Palmdale | E9: 697 | F9: =E9/'County Plans'!$G$26 -> 0.01035492 | G9: =E9*'County Plans'!$B$15 -> 174.25 | H9: =G9*'County Plans'!$B$16/1000 -> 47.91875 | I9: =G9*'County Plans'!$B$17/1000 -> 95.8375 | J9: =ROUNDUP(H9/'County Plans'!$B$21,0) -> 1 | K9: =ROUNDUP(I9/'County Plans'!$B$21,0) -> 1 | L9: =J9*'County Plans'!$B$6 -> 10000 | M9: =J9*'County Plans'!$B$7 -> 58333 | N9: =J9*'County Plans'!$B$8 -> 104643.75 | O9: =J9*'County Plans'!$B$9 -> 589147
A10: Los Angeles County, CA | B10: 6 | C10: 93534 | D10: Lancaster | E10: 678 | F10: =E10/'County Plans'!$G$26 -> 0.010072648 | G10: =E10*'County Plans'!$B$15 -> 169.5 | H10: =G10*'County Plans'!$B$16/1000 -> 46.6125 | I10: =G10*'County Plans'!$B$17/1000 -> 93.225 | J10: =ROUNDUP(H10/'County Plans'!$B$21,0) -> 1 | K10: =ROUNDUP(I10/'County Plans'!$B$21,0) -> 1 | L10: =J10*'County Plans'!$B$6 -> 10000 | M10: =J10*'County Plans'!$B$7 -> 58333 | N10: =J10*'County Plans'!$B$8 -> 104643.75 | O10: =J10*'County Plans'!$B$9 -> 589147
A11: Los Angeles County, CA | B11: 7 | C11: 91331 | D11: Pacoima | E11: 658 | F11: =E11/'County Plans'!$G$26 -> 0.0097755196 | G11: =E11*'County Plans'!$B$15 -> 164.5 | H11: =G11*'County Plans'!$B$16/1000 -> 45.2375 | I11: =G11*'County Plans'!$B$17/1000 -> 90.475 | J11: =ROUNDUP(H11/'County Plans'!$B$21,0) -> 1 | K11: =ROUNDUP(I11/'County Plans'!$B$21,0) -> 1 | L11: =J11*'County Plans'!$B$6 -> 10000 | M11: =J11*'County Plans'!$B$7 -> 58333 | N11: =J11*'County Plans'!$B$8 -> 104643.75 | O11: =J11*'County Plans'!$B$9 -> 589147
A12: Los Angeles County, CA | B12: 8 | C12: 91335 | D12: Reseda | E12: 633 | F12: =E12/'County Plans'!$G$26 -> 0.0094041093 | G12: =E12*'County Plans'!$B$15 -> 158.25 | H12: =G12*'County Plans'!$B$16/1000 -> 43.51875 | I12: =G12*'County Plans'!$B$17/1000 -> 87.0375 | J12: =ROUNDUP(H12/'County Plans'!$B$21,0) -> 1 | K12: =ROUNDUP(I12/'County Plans'!$B$21,0) -> 1 | L12: =J12*'County Plans'!$B$6 -> 10000 | M12: =J12*'County Plans'!$B$7 -> 58333 | N12: =J12*'County Plans'!$B$8 -> 104643.75 | O12: =J12*'County Plans'!$B$9 -> 589147
A13: Los Angeles County, CA | B13: 9 | C13: 90044 | D13: Los Angeles | E13: 620 | F13: =E13/'County Plans'!$G$26 -> 0.0092109759 | G13: =E13*'County Plans'!$B$15 -> 155 | H13: =G13*'County Plans'!$B$16/1000 -> 42.625 | I13: =G13*'County Plans'!$B$17/1000 -> 85.25 | J13: =ROUNDUP(H13/'County Plans'!$B$21,0) -> 1 | K13: =ROUNDUP(I13/'County Plans'!$B$21,0) -> 1 | L13: =J13*'County Plans'!$B$6 -> 10000 | M13: =J13*'County Plans'!$B$7 -> 58333 | N13: =J13*'County Plans'!$B$8 -> 104643.75 | O13: =J13*'County Plans'!$B$9 -> 589147
A14: Los Angeles County, CA | B14: 10 | C14: 91744 | D14: La Puente | E14: 581 | F14: =E14/'County Plans'!$G$26 -> 0.0086315758 | G14: =E14*'County Plans'!$B$15 -> 145.25 | H14: =G14*'County Plans'!$B$16/1000 -> 39.94375 | I14: =G14*'County Plans'!$B$17/1000 -> 79.8875 | J14: =ROUNDUP(H14/'County Plans'!$B$21,0) -> 1 | K14: =ROUNDUP(I14/'County Plans'!$B$21,0) -> 1 | L14: =J14*'County Plans'!$B$6 -> 10000 | M14: =J14*'County Plans'!$B$7 -> 58333 | N14: =J14*'County Plans'!$B$8 -> 104643.75 | O14: =J14*'County Plans'!$B$9 -> 589147
A15: Los Angeles County, CA: top 10 ZIPs | E15: =SUM(E5:E14) -> 6885 | F15: =SUM(F5:F14) -> 0.1022864 | G15: =SUM(G5:G14) -> 1721.25 | H15: =SUM(H5:H14) -> 473.34375 | I15: =SUM(I5:I14) -> 946.6875 | J15: =SUM(J5:J14) -> 10 | K15: =SUM(K5:K14) -> 12 | L15: =SUM(L5:L14) -> 100000 | ... O15: =SUM(O5:O14) -> 5891470
A17: Cook County, IL | B17: 1 | C17: 60620 | D17: Chicago | E17: 755 | F17: =E17/'County Plans'!$G$27 -> 0.022487639 | G17: =E17*'County Plans'!$B$15 -> 188.75 | H17: =G17*'County Plans'!$B$16/1000 -> 51.90625 | I17: =G17*'County Plans'!$B$17/1000 -> 103.8125 | J17: =ROUNDUP(H17/'County Plans'!$B$21,0) -> 1 | K17: =ROUNDUP(I17/'County Plans'!$B$21,0) -> 2 | L17: =J17*'County Plans'!$B$6 -> 10000 | M17: =J17*'County Plans'!$B$7 -> 58333 | N17: =J17*'County Plans'!$B$8 -> 104643.75 | O17: =J17*'County Plans'!$B$9 -> 589147
A18: Cook County, IL | B18: 2 | C18: 60617 | D18: Chicago | E18: 724 | F18: =E18/'County Plans'!$G$27 -> 0.021564306 | G18: =E18*'County Plans'!$B$15 -> 181 | H18: =G18*'County Plans'!$B$16/1000 -> 49.775 | I18: =G18*'County Plans'!$B$17/1000 -> 99.55 | J18: =ROUNDUP(H18/'County Plans'!$B$21,0) -> 1 | K18: =ROUNDUP(I18/'County Plans'!$B$21,0) -> 1 | L18: =J18*'County Plans'!$B$6 -> 10000 | M18: =J18*'County Plans'!$B$7 -> 58333 | N18: =J18*'County Plans'!$B$8 -> 104643.75 | O18: =J18*'County Plans'!$B$9 -> 589147
A19: Cook County, IL | B19: 3 | C19: 60628 | D19: Chicago | E19: 712 | F19: =E19/'County Plans'!$G$27 -> 0.021206886 | G19: =E19*'County Plans'!$B$15 -> 178 | H19: =G19*'County Plans'!$B$16/1000 -> 48.95 | I19: =G19*'County Plans'!$B$17/1000 -> 97.9 | J19: =ROUNDUP(H19/'County Plans'!$B$21,0) -> 1 | K19: =ROUNDUP(I19/'County Plans'!$B$21,0) -> 1 | L19: =J19*'County Plans'!$B$6 -> 10000 | M19: =J19*'County Plans'!$B$7 -> 58333 | N19: =J19*'County Plans'!$B$8 -> 104643.75 | O19: =J19*'County Plans'!$B$9 -> 589147
A20: Cook County, IL | B20: 4 | C20: 60619 | D20: Chicago | E20: 661 | F20: =E20/'County Plans'!$G$27 -> 0.019687854 | G20: =E20*'County Plans'!$B$15 -> 165.25 | H20: =G20*'County Plans'!$B$16/1000 -> 45.44375 | I20: =G20*'County Plans'!$B$17/1000 -> 90.8875 | J20: =ROUNDUP(H20/'County Plans'!$B$21,0) -> 1 | K20: =ROUNDUP(I20/'County Plans'!$B$21,0) -> 1 | L20: =J20*'County Plans'!$B$6 -> 10000 | M20: =J20*'County Plans'!$B$7 -> 58333 | N20: =J20*'County Plans'!$B$8 -> 104643.75 | O20: =J20*'County Plans'!$B$9 -> 589147
A21: Cook County, IL | B21: 5 | C21: 60411 | D21: Chicago Heights | E21: 558 | F21: =E21/'County Plans'!$G$27 -> 0.016620004 | G21: =E21*'County Plans'!$B$15 -> 139.5 | H21: =G21*'County Plans'!$B$16/1000 -> 38.3625 | I21: =G21*'County Plans'!$B$17/1000 -> 76.725 | J21: =ROUNDUP(H21/'County Plans'!$B$21,0) -> 1 | K21: =ROUNDUP(I21/'County Plans'!$B$21,0) -> 1 | L21: =J21*'County Plans'!$B$6 -> 10000 | M21: =J21*'County Plans'!$B$7 -> 58333 | N21: =J21*'County Plans'!$B$8 -> 104643.75 | O21: =J21*'County Plans'!$B$9 -> 589147
A22: Cook County, IL | B22: 6 | C22: 60643 | D22: Chicago | E22: 527 | F22: =E22/'County Plans'!$G$27 -> 0.01569667 | G22: =E22*'County Plans'!$B$15 -> 131.75 | H22: =G22*'County Plans'!$B$16/1000 -> 36.23125 | I22: =G22*'County Plans'!$B$17/1000 -> 72.4625 | J22: =ROUNDUP(H22/'County Plans'!$B$21,0) -> 1 | K22: =ROUNDUP(I22/'County Plans'!$B$21,0) -> 1 | L22: =J22*'County Plans'!$B$6 -> 10000 | M22: =J22*'County Plans'!$B$7 -> 58333 | N22: =J22*'County Plans'!$B$8 -> 104643.75 | O22: =J22*'County Plans'!$B$9 -> 589147
A23: Cook County, IL | B23: 7 | C23: 60453 | D23: Oak Lawn | E23: 517 | F23: =E23/'County Plans'!$G$27 -> 0.015398821 | G23: =E23*'County Plans'!$B$15 -> 129.25 | H23: =G23*'County Plans'!$B$16/1000 -> 35.54375 | I23: =G23*'County Plans'!$B$17/1000 -> 71.0875 | J23: =ROUNDUP(H23/'County Plans'!$B$21,0) -> 1 | K23: =ROUNDUP(I23/'County Plans'!$B$21,0) -> 1 | L23: =J23*'County Plans'!$B$6 -> 10000 | M23: =J23*'County Plans'!$B$7 -> 58333 | N23: =J23*'County Plans'!$B$8 -> 104643.75 | O23: =J23*'County Plans'!$B$9 -> 589147
A24: Cook County, IL | B24: 8 | C24: 60629 | D24: Chicago | E24: 502 | F24: =E24/'County Plans'!$G$27 -> 0.014952046 | G24: =E24*'County Plans'!$B$15 -> 125.5 | H24: =G24*'County Plans'!$B$16/1000 -> 34.5125 | I24: =G24*'County Plans'!$B$17/1000 -> 69.025 | J24: =ROUNDUP(H24/'County Plans'!$B$21,0) -> 1 | K24: =ROUNDUP(I24/'County Plans'!$B$21,0) -> 1 | L24: =J24*'County Plans'!$B$6 -> 10000 | M24: =J24*'County Plans'!$B$7 -> 58333 | N24: =J24*'County Plans'!$B$8 -> 104643.75 | O24: =J24*'County Plans'!$B$9 -> 589147
A25: Cook County, IL | B25: 9 | C25: 60409 | D25: Calumet City | E25: 423 | F25: =E25/'County Plans'!$G$27 -> 0.012599035 | G25: =E25*'County Plans'!$B$15 -> 105.75 | H25: =G25*'County Plans'!$B$16/1000 -> 29.08125 | I25: =G25*'County Plans'!$B$17/1000 -> 58.1625 | J25: =ROUNDUP(H25/'County Plans'!$B$21,0) -> 1 | K25: =ROUNDUP(I25/'County Plans'!$B$21,0) -> 1 | L25: =J25*'County Plans'!$B$6 -> 10000 | M25: =J25*'County Plans'!$B$7 -> 58333 | N25: =J25*'County Plans'!$B$8 -> 104643.75 | O25: =J25*'County Plans'!$B$9 -> 589147
A26: Cook County, IL | B26: 10 | C26: 60634 | D26: Chicago | E26: 415 | F26: =E26/'County Plans'!$G$27 -> 0.012360755 | G26: =E26*'County Plans'!$B$15 -> 103.75 | H26: =G26*'County Plans'!$B$16/1000 -> 28.53125 | I26: =G26*'County Plans'!$B$17/1000 -> 57.0625 | J26: =ROUNDUP(H26/'County Plans'!$B$21,0) -> 1 | K26: =ROUNDUP(I26/'County Plans'!$B$21,0) -> 1 | L26: =J26*'County Plans'!$B$6 -> 10000 | M26: =J26*'County Plans'!$B$7 -> 58333 | N26: =J26*'County Plans'!$B$8 -> 104643.75 | O26: =J26*'County Plans'!$B$9 -> 589147
A27: Cook County, IL: top 10 ZIPs | E27: =SUM(E17:E26) -> 5794 | F27: =SUM(F17:F26) -> 0.17257402 | G27: =SUM(G17:G26) -> 1448.5 | H27: =SUM(H17:H26) -> 398.3375 | I27: =SUM(I17:I26) -> 796.675 | J27: =SUM(J17:J26) -> 10 | K27: =SUM(K17:K26) -> 11 | L27: =SUM(L17:L26) -> 100000 | ... O27: =SUM(O17:O26) -> 5891470
A29: Harris County, TX | B29: 1 | C29: 77449 | D29: Katy | E29: 648 | F29: =E29/'County Plans'!$G$28 -> 0.02249141 | G29: =E29*'County Plans'!$B$15 -> 162 | H29: =G29*'County Plans'!$B$16/1000 -> 44.55 | I29: =G29*'County Plans'!$B$17/1000 -> 89.1 | J29: =ROUNDUP(H29/'County Plans'!$B$21,0) -> 1 | K29: =ROUNDUP(I29/'County Plans'!$B$21,0) -> 1 | L29: =J29*'County Plans'!$B$6 -> 10000 | M29: =J29*'County Plans'!$B$7 -> 58333 | N29: =J29*'County Plans'!$B$8 -> 104643.75 | O29: =J29*'County Plans'!$B$9 -> 589147
A30: Harris County, TX | B30: 2 | C30: 77379 | D30: Spring | E30: 577 | F30: =E30/'County Plans'!$G$28 -> 0.020027073 | G30: =E30*'County Plans'!$B$15 -> 144.25 | H30: =G30*'County Plans'!$B$16/1000 -> 39.66875 | I30: =G30*'County Plans'!$B$17/1000 -> 79.3375 | J30: =ROUNDUP(H30/'County Plans'!$B$21,0) -> 1 | K30: =ROUNDUP(I30/'County Plans'!$B$21,0) -> 1 | L30: =J30*'County Plans'!$B$6 -> 10000 | M30: =J30*'County Plans'!$B$7 -> 58333 | N30: =J30*'County Plans'!$B$8 -> 104643.75 | O30: =J30*'County Plans'!$B$9 -> 589147
A31: Harris County, TX | B31: 3 | C31: 77084 | D31: Houston | E31: 563 | F31: =E31/'County Plans'!$G$28 -> 0.019541147 | G31: =E31*'County Plans'!$B$15 -> 140.75 | H31: =G31*'County Plans'!$B$16/1000 -> 38.70625 | I31: =G31*'County Plans'!$B$17/1000 -> 77.4125 | J31: =ROUNDUP(H31/'County Plans'!$B$21,0) -> 1 | K31: =ROUNDUP(I31/'County Plans'!$B$21,0) -> 1 | L31: =J31*'County Plans'!$B$6 -> 10000 | M31: =J31*'County Plans'!$B$7 -> 58333 | N31: =J31*'County Plans'!$B$8 -> 104643.75 | O31: =J31*'County Plans'!$B$9 -> 589147
A32: Harris County, TX | B32: 4 | C32: 77521 | D32: Baytown | E32: 531 | F32: =E32/'County Plans'!$G$28 -> 0.018430461 | G32: =E32*'County Plans'!$B$15 -> 132.75 | H32: =G32*'County Plans'!$B$16/1000 -> 36.50625 | I32: =G32*'County Plans'!$B$17/1000 -> 73.0125 | J32: =ROUNDUP(H32/'County Plans'!$B$21,0) -> 1 | K32: =ROUNDUP(I32/'County Plans'!$B$21,0) -> 1 | L32: =J32*'County Plans'!$B$6 -> 10000 | M32: =J32*'County Plans'!$B$7 -> 58333 | N32: =J32*'County Plans'!$B$8 -> 104643.75 | O32: =J32*'County Plans'!$B$9 -> 589147
A33: Harris County, TX | B33: 5 | C33: 77429 | D33: Cypress | E33: 530 | F33: =E33/'County Plans'!$G$28 -> 0.018395752 | G33: =E33*'County Plans'!$B$15 -> 132.5 | H33: =G33*'County Plans'!$B$16/1000 -> 36.4375 | I33: =G33*'County Plans'!$B$17/1000 -> 72.875 | J33: =ROUNDUP(H33/'County Plans'!$B$21,0) -> 1 | K33: =ROUNDUP(I33/'County Plans'!$B$21,0) -> 1 | L33: =J33*'County Plans'!$B$6 -> 10000 | M33: =J33*'County Plans'!$B$7 -> 58333 | N33: =J33*'County Plans'!$B$8 -> 104643.75 | O33: =J33*'County Plans'!$B$9 -> 589147
A34: Harris County, TX | B34: 6 | C34: 77433 | D34: Cypress | E34: 524 | F34: =E34/'County Plans'!$G$28 -> 0.018187498 | G34: =E34*'County Plans'!$B$15 -> 131 | H34: =G34*'County Plans'!$B$16/1000 -> 36.025 | I34: =G34*'County Plans'!$B$17/1000 -> 72.05 | J34: =ROUNDUP(H34/'County Plans'!$B$21,0) -> 1 | K34: =ROUNDUP(I34/'County Plans'!$B$21,0) -> 1 | L34: =J34*'County Plans'!$B$6 -> 10000 | M34: =J34*'County Plans'!$B$7 -> 58333 | N34: =J34*'County Plans'!$B$8 -> 104643.75 | O34: =J34*'County Plans'!$B$9 -> 589147
A35: Harris County, TX | B35: 7 | C35: 77088 | D35: Houston | E35: 453 | F35: =E35/'County Plans'!$G$28 -> 0.015723161 | G35: =E35*'County Plans'!$B$15 -> 113.25 | H35: =G35*'County Plans'!$B$16/1000 -> 31.14375 | I35: =G35*'County Plans'!$B$17/1000 -> 62.2875 | J35: =ROUNDUP(H35/'County Plans'!$B$21,0) -> 1 | K35: =ROUNDUP(I35/'County Plans'!$B$21,0) -> 1 | L35: =J35*'County Plans'!$B$6 -> 10000 | M35: =J35*'County Plans'!$B$7 -> 58333 | N35: =J35*'County Plans'!$B$8 -> 104643.75 | O35: =J35*'County Plans'!$B$9 -> 589147
A36: Harris County, TX | B36: 8 | C36: 77346 | D36: Humble | E36: 451 | F36: =E36/'County Plans'!$G$28 -> 0.015653743 | G36: =E36*'County Plans'!$B$15 -> 112.75 | H36: =G36*'County Plans'!$B$16/1000 -> 31.00625 | I36: =G36*'County Plans'!$B$17/1000 -> 62.0125 | J36: =ROUNDUP(H36/'County Plans'!$B$21,0) -> 1 | K36: =ROUNDUP(I36/'County Plans'!$B$21,0) -> 1 | L36: =J36*'County Plans'!$B$6 -> 10000 | M36: =J36*'County Plans'!$B$7 -> 58333 | N36: =J36*'County Plans'!$B$8 -> 104643.75 | O36: =J36*'County Plans'!$B$9 -> 589147
A37: Harris County, TX | B37: 9 | C37: 77083 | D37: Houston | E37: 435 | F37: =E37/'County Plans'!$G$28 -> 0.0150984 | G37: =E37*'County Plans'!$B$15 -> 108.75 | H37: =G37*'County Plans'!$B$16/1000 -> 29.90625 | I37: =G37*'County Plans'!$B$17/1000 -> 59.8125 | J37: =ROUNDUP(H37/'County Plans'!$B$21,0) -> 1 | K37: =ROUNDUP(I37/'County Plans'!$B$21,0) -> 1 | L37: =J37*'County Plans'!$B$6 -> 10000 | M37: =J37*'County Plans'!$B$7 -> 58333 | N37: =J37*'County Plans'!$B$8 -> 104643.75 | O37: =J37*'County Plans'!$B$9 -> 589147
A38: Harris County, TX | B38: 10 | C38: 77095 | D38: Houston | E38: 413 | F38: =E38/'County Plans'!$G$28 -> 0.014334803 | G38: =E38*'County Plans'!$B$15 -> 103.25 | H38: =G38*'County Plans'!$B$16/1000 -> 28.39375 | I38: =G38*'County Plans'!$B$17/1000 -> 56.7875 | J38: =ROUNDUP(H38/'County Plans'!$B$21,0) -> 1 | K38: =ROUNDUP(I38/'County Plans'!$B$21,0) -> 1 | L38: =J38*'County Plans'!$B$6 -> 10000 | M38: =J38*'County Plans'!$B$7 -> 58333 | N38: =J38*'County Plans'!$B$8 -> 104643.75 | O38: =J38*'County Plans'!$B$9 -> 589147
A39: Harris County, TX: top 10 ZIPs | E39: =SUM(E29:E38) -> 5125 | F39: =SUM(F29:F38) -> 0.17788345 | G39: =SUM(G29:G38) -> 1281.25 | H39: =SUM(H29:H38) -> 352.34375 | I39: =SUM(I29:I38) -> 704.6875 | J39: =SUM(J29:J38) -> 10 | K39: =SUM(K29:K38) -> 10 | L39: =SUM(L29:L38) -> 100000 | ... O39: =SUM(O29:O38) -> 5891470
A41: Maricopa County, AZ | B41: 1 | C41: 85351 | D41: Sun City | E41: 901 | F41: =E41/'County Plans'!$G$29 -> 0.027400176 | G41: =E41*'County Plans'!$B$15 -> 225.25 | H41: =G41*'County Plans'!$B$16/1000 -> 61.94375 | I41: =G41*'County Plans'!$B$17/1000 -> 123.8875 | J41: =ROUNDUP(H41/'County Plans'!$B$21,0) -> 1 | K41: =ROUNDUP(I41/'County Plans'!$B$21,0) -> 2 | L41: =J41*'County Plans'!$B$6 -> 10000 | M41: =J41*'County Plans'!$B$7 -> 58333 | N41: =J41*'County Plans'!$B$8 -> 104643.75 | O41: =J41*'County Plans'!$B$9 -> 589147
A42: Maricopa County, AZ | B42: 2 | C42: 85375 | D42: Sun City West | E42: 784 | F42: =E42/'County Plans'!$G$29 -> 0.023842107 | G42: =E42*'County Plans'!$B$15 -> 196 | H42: =G42*'County Plans'!$B$16/1000 -> 53.9 | I42: =G42*'County Plans'!$B$17/1000 -> 107.8 | J42: =ROUNDUP(H42/'County Plans'!$B$21,0) -> 1 | K42: =ROUNDUP(I42/'County Plans'!$B$21,0) -> 2 | L42: =J42*'County Plans'!$B$6 -> 10000 | M42: =J42*'County Plans'!$B$7 -> 58333 | N42: =J42*'County Plans'!$B$8 -> 104643.75 | O42: =J42*'County Plans'!$B$9 -> 589147
A43: Maricopa County, AZ | B43: 3 | C43: 85374 | D43: Surprise | E43: 689 | F43: =E43/'County Plans'!$G$29 -> 0.020953076 | G43: =E43*'County Plans'!$B$15 -> 172.25 | H43: =G43*'County Plans'!$B$16/1000 -> 47.36875 | I43: =G43*'County Plans'!$B$17/1000 -> 94.7375 | J43: =ROUNDUP(H43/'County Plans'!$B$21,0) -> 1 | K43: =ROUNDUP(I43/'County Plans'!$B$21,0) -> 1 | L43: =J43*'County Plans'!$B$6 -> 10000 | M43: =J43*'County Plans'!$B$7 -> 58333 | N43: =J43*'County Plans'!$B$8 -> 104643.75 | O43: =J43*'County Plans'!$B$9 -> 589147
A44: Maricopa County, AZ | B44: 4 | C44: 85345 | D44: Peoria | E44: 569 | F44: =E44/'County Plans'!$G$29 -> 0.017303774 | G44: =E44*'County Plans'!$B$15 -> 142.25 | H44: =G44*'County Plans'!$B$16/1000 -> 39.11875 | I44: =G44*'County Plans'!$B$17/1000 -> 78.2375 | J44: =ROUNDUP(H44/'County Plans'!$B$21,0) -> 1 | K44: =ROUNDUP(I44/'County Plans'!$B$21,0) -> 1 | L44: =J44*'County Plans'!$B$6 -> 10000 | M44: =J44*'County Plans'!$B$7 -> 58333 | N44: =J44*'County Plans'!$B$8 -> 104643.75 | O44: =J44*'County Plans'!$B$9 -> 589147
...
